#VRML_SIM R2023b utf8

EXTERNPROTO "https://raw.githubusercontent.com/cyberbotics/webots/R2023b/projects/objects/backgrounds/protos/TexturedBackground.proto"
EXTERNPROTO "https://raw.githubusercontent.com/cyberbotics/webots/R2023b/projects/objects/backgrounds/protos/TexturedBackgroundLight.proto"
EXTERNPROTO "https://raw.githubusercontent.com/cyberbotics/webots/R2023b/projects/objects/floors/protos/RectangleArena.proto"

WorldInfo {
  title "HexapodBasicSim"
}
Viewpoint {
  orientation 0.20144791102367013 -0.2667262645445002 -0.9424838666769512 4.618415752370602
  position 0.24395494485078242 -3.329819633188817 2.1845297723878465
}
TexturedBackground {
}
TexturedBackgroundLight {
}
RectangleArena {
  floorSize 10 10
}
Robot {
  children [
    DEF BaseTransform Pose {
      translation 0 0 0.05
      children [
        DEF NewTorso Shape {
          appearance PBRAppearance {
            baseColor 0.505882 0.239216 0.611765
            roughness 1
            metalness 0
          }
          geometry Box {
            size 0.2 0.3 0.05
          }
        }
      ]
    }
    DEF RobotBody Pose {
      translation 0 0 0.05
      children [
        DEF L5J1 HingeJoint {
          jointParameters HingeJointParameters {
            position 3.14
            axis 0 0 1
            anchor -0.1 0 0
          }
          device [
            RotationalMotor {
              name "Servo51"
            }
          ]
          endPoint Solid {
            translation -0.100119 -5.1536660884503836e-20 -1.42681e-05
            rotation 0.0005622220463405378 0.7071079756357186 0.707105363222997 3.140466234838101
            children [
              DEF L2MountServoTransform Pose {
                rotation 1 0 0 -1.5708
                children [
                  DEF MountPoint Shape {
                    appearance PBRAppearance {
                      baseColor 0.380392 0.207843 0.513726
                      metalness 0
                    }
                    geometry Cylinder {
                      height 0.06
                      radius 0.01
                    }
                  }
                ]
              }
              DEF A1_Transform Pose {
                translation 0.0315 0 0
                children [
                  DEF A1 Shape {
                    appearance PBRAppearance {
                      baseColor 0.898039 0.647059 0.0392157
                      metalness 0
                    }
                    geometry Box {
                      size 0.063 0.02 0.02
                    }
                  }
                ]
              }
              DEF L5J2 HingeJoint {
                jointParameters HingeJointParameters {
                  axis 0 0 1
                  anchor 0.063 0 0
                }
                device [
                  DEF Servo12 RotationalMotor {
                    name "Servo52"
                  }
                ]
                endPoint Solid {
                  translation 0.06300000000000001 -4.311275944295536e-18 0
                  children [
                    DEF A2_Transform Pose {
                      translation 0.045 0 0
                      children [
                        DEF A2 Shape {
                          appearance PBRAppearance {
                            baseColor 1 0.470588 0
                            metalness 0
                          }
                          geometry Box {
                            size 0.09 0.02 0.02
                          }
                        }
                      ]
                    }
                    DEF L5J3 HingeJoint {
                      jointParameters HingeJointParameters {
                        axis 0 0 1
                        anchor 0.09 0 0
                      }
                      device [
                        DEF Servo13 RotationalMotor {
                          name "Servo53"
                        }
                      ]
                      endPoint Solid {
                        translation 0.09 0 0
                        children [
                          DEF A3_Transform Pose {
                            translation 0.115 0 0
                            children [
                              DEF A3 Shape {
                                appearance PBRAppearance {
                                  baseColor 0.14902 0.635294 0.411765
                                  metalness 0
                                }
                                geometry Box {
                                  size 0.23 0.02 0.02
                                }
                              }
                            ]
                          }
                          Shape {
                            appearance PBRAppearance {
                              baseColor 0.380392 0.207843 0.513726
                              metalness 0
                            }
                            geometry Cylinder {
                              height 0.025
                              radius 0.0125
                            }
                          }
                        ]
                        boundingObject USE A3_Transform
                        physics Physics {
                        }
                      }
                    }
                    Shape {
                      appearance PBRAppearance {
                        baseColor 0.380392 0.207843 0.513726
                        metalness 0
                      }
                      geometry Cylinder {
                        height 0.025
                        radius 0.0125
                      }
                    }
                  ]
                  boundingObject USE A2_Transform
                  physics Physics {
                  }
                }
              }
            ]
            name "solid(5)"
            boundingObject USE A1_Transform
            physics Physics {
            }
          }
        }
        DEF L2J1 HingeJoint {
          jointParameters HingeJointParameters {
            axis 0 0 1
            anchor 0.1 0 0
          }
          device [
            RotationalMotor {
              name "Servo21"
            }
          ]
          endPoint Solid {
            translation 0.1 0 -1.42681e-05
            rotation 0.9999999999992331 1.2262625356379814e-06 -1.7305524664364949e-07 1.5708000201914338
            children [
              DEF MountServoTransform Pose {
                rotation 1 0 0 -1.5708
                children [
                  DEF MountPoint Shape {
                    appearance PBRAppearance {
                      baseColor 0.380392 0.207843 0.513726
                      metalness 0
                    }
                    geometry Cylinder {
                      height 0.06
                      radius 0.01
                    }
                  }
                ]
              }
              DEF A1_Transform Pose {
                translation 0.0315 0 0
                children [
                  DEF A1 Shape {
                    appearance PBRAppearance {
                      baseColor 0.898039 0.647059 0.0392157
                      metalness 0
                    }
                    geometry Box {
                      size 0.063 0.02 0.02
                    }
                  }
                ]
              }
              DEF L2J2 HingeJoint {
                jointParameters HingeJointParameters {
                  axis 0 0 1
                  anchor 0.063 0 0
                }
                device [
                  DEF Servo12 RotationalMotor {
                    name "Servo22"
                  }
                ]
                endPoint Solid {
                  translation 0.06300000000000001 -4.311275944295536e-18 0
                  children [
                    DEF A2_Transform Pose {
                      translation 0.045 0 0
                      children [
                        DEF A2 Shape {
                          appearance PBRAppearance {
                            baseColor 1 0.470588 0
                            metalness 0
                          }
                          geometry Box {
                            size 0.09 0.02 0.02
                          }
                        }
                      ]
                    }
                    DEF L2J3 HingeJoint {
                      jointParameters HingeJointParameters {
                        axis 0 0 1
                        anchor 0.09 0 0
                      }
                      device [
                        DEF Servo13 RotationalMotor {
                          name "Servo23"
                        }
                      ]
                      endPoint Solid {
                        translation 0.09 0 0
                        children [
                          DEF A3_Transform Pose {
                            translation 0.115 0 0
                            children [
                              DEF A3 Shape {
                                appearance PBRAppearance {
                                  baseColor 0.14902 0.635294 0.411765
                                  metalness 0
                                }
                                geometry Box {
                                  size 0.23 0.02 0.02
                                }
                              }
                            ]
                          }
                          Shape {
                            appearance PBRAppearance {
                              baseColor 0.380392 0.207843 0.513726
                              metalness 0
                            }
                            geometry Cylinder {
                              height 0.025
                              radius 0.0125
                            }
                          }
                        ]
                        boundingObject USE A3_Transform
                        physics Physics {
                        }
                      }
                    }
                    Shape {
                      appearance PBRAppearance {
                        baseColor 0.380392 0.207843 0.513726
                        metalness 0
                      }
                      geometry Cylinder {
                        height 0.025
                        radius 0.0125
                      }
                    }
                  ]
                  boundingObject USE A2_Transform
                  physics Physics {
                  }
                }
              }
            ]
            name "solid(4)"
            boundingObject USE A1_Transform
            physics Physics {
            }
          }
        }
        DEF L6J1 HingeJoint {
          jointParameters HingeJointParameters {
            position -3.14
            axis 0 0 1
            anchor -0.1 -0.15 0
          }
          device [
            RotationalMotor {
              name "Servo61"
            }
          ]
          endPoint Solid {
            translation -0.1 -0.15 -1.42681e-05
            rotation 0.0005639562406061203 -0.7071079670185496 -0.7071053704592072 3.1404667243017093
            children [
              DEF MountServoTransform Pose {
                rotation 1 0 0 -1.5708
                children [
                  DEF MountPoint Shape {
                    appearance PBRAppearance {
                      baseColor 0.380392 0.207843 0.513726
                      metalness 0
                    }
                    geometry Cylinder {
                      height 0.06
                      radius 0.01
                    }
                  }
                ]
              }
              DEF A1_Transform Pose {
                translation 0.0315 0 0
                children [
                  DEF A1 Shape {
                    appearance PBRAppearance {
                      baseColor 0.898039 0.647059 0.0392157
                      metalness 0
                    }
                    geometry Box {
                      size 0.063 0.02 0.02
                    }
                  }
                ]
              }
              DEF L6J2 HingeJoint {
                jointParameters HingeJointParameters {
                  axis 0 0 1
                  anchor 0.063 0 0
                }
                device [
                  DEF Servo12 RotationalMotor {
                    name "Servo62"
                  }
                ]
                endPoint Solid {
                  translation 0.06300000000000001 -4.311275944295536e-18 0
                  children [
                    DEF A2_Transform Pose {
                      translation 0.045 0 0
                      children [
                        DEF A2 Shape {
                          appearance PBRAppearance {
                            baseColor 1 0.470588 0
                            metalness 0
                          }
                          geometry Box {
                            size 0.09 0.02 0.02
                          }
                        }
                      ]
                    }
                    DEF L6J3 HingeJoint {
                      jointParameters HingeJointParameters {
                        axis 0 0 1
                        anchor 0.09 0 0
                      }
                      device [
                        DEF Servo13 RotationalMotor {
                          name "Servo63"
                        }
                      ]
                      endPoint Solid {
                        translation 0.09 0 0
                        children [
                          DEF A3_Transform Pose {
                            translation 0.115 0 0
                            children [
                              DEF A3 Shape {
                                appearance PBRAppearance {
                                  baseColor 0.14902 0.635294 0.411765
                                  metalness 0
                                }
                                geometry Box {
                                  size 0.23 0.02 0.02
                                }
                              }
                            ]
                          }
                          Shape {
                            appearance PBRAppearance {
                              baseColor 0.380392 0.207843 0.513726
                              metalness 0
                            }
                            geometry Cylinder {
                              height 0.025
                              radius 0.0125
                            }
                          }
                        ]
                        boundingObject USE A3_Transform
                        physics Physics {
                        }
                      }
                    }
                    Shape {
                      appearance PBRAppearance {
                        baseColor 0.380392 0.207843 0.513726
                        metalness 0
                      }
                      geometry Cylinder {
                        height 0.025
                        radius 0.0125
                      }
                    }
                  ]
                  boundingObject USE A2_Transform
                  physics Physics {
                  }
                }
              }
            ]
            name "solid(3)"
            boundingObject USE A1_Transform
            physics Physics {
            }
          }
        }
        DEF L3J1 HingeJoint {
          jointParameters HingeJointParameters {
            axis 0 0 1
            anchor 0.1 -0.15 0
          }
          device [
            RotationalMotor {
              name "Servo31"
            }
          ]
          endPoint Solid {
            translation 0.1 -0.15 -1.42681e-05
            rotation 0.9999999999992331 1.2262625356379814e-06 -1.7305524664364949e-07 1.5708000201914338
            children [
              DEF MountServoTransform Pose {
                rotation 1 0 0 -1.5708
                children [
                  DEF MountPoint Shape {
                    appearance PBRAppearance {
                      baseColor 0.380392 0.207843 0.513726
                      metalness 0
                    }
                    geometry Cylinder {
                      height 0.06
                      radius 0.01
                    }
                  }
                ]
              }
              DEF A1_Transform Pose {
                translation 0.0315 0 0
                children [
                  DEF A1 Shape {
                    appearance PBRAppearance {
                      baseColor 0.898039 0.647059 0.0392157
                      metalness 0
                    }
                    geometry Box {
                      size 0.063 0.02 0.02
                    }
                  }
                ]
              }
              DEF L3J2 HingeJoint {
                jointParameters HingeJointParameters {
                  axis 0 0 1
                  anchor 0.063 0 0
                }
                device [
                  DEF Servo12 RotationalMotor {
                    name "Servo32"
                  }
                ]
                endPoint Solid {
                  translation 0.06300000000000001 -4.311275944295536e-18 0
                  children [
                    DEF A2_Transform Pose {
                      translation 0.045 0 0
                      children [
                        DEF A2 Shape {
                          appearance PBRAppearance {
                            baseColor 1 0.470588 0
                            metalness 0
                          }
                          geometry Box {
                            size 0.09 0.02 0.02
                          }
                        }
                      ]
                    }
                    DEF L3J3 HingeJoint {
                      jointParameters HingeJointParameters {
                        axis 0 0 1
                        anchor 0.09 0 0
                      }
                      device [
                        DEF Servo13 RotationalMotor {
                          name "Servo33"
                        }
                      ]
                      endPoint Solid {
                        translation 0.09 0 0
                        children [
                          DEF A3_Transform Pose {
                            translation 0.115 0 0
                            children [
                              DEF A3 Shape {
                                appearance PBRAppearance {
                                  baseColor 0.14902 0.635294 0.411765
                                  metalness 0
                                }
                                geometry Box {
                                  size 0.23 0.02 0.02
                                }
                              }
                            ]
                          }
                          Shape {
                            appearance PBRAppearance {
                              baseColor 0.380392 0.207843 0.513726
                              metalness 0
                            }
                            geometry Cylinder {
                              height 0.025
                              radius 0.0125
                            }
                          }
                        ]
                        boundingObject USE A3_Transform
                        physics Physics {
                        }
                      }
                    }
                    Shape {
                      appearance PBRAppearance {
                        baseColor 0.380392 0.207843 0.513726
                        metalness 0
                      }
                      geometry Cylinder {
                        height 0.025
                        radius 0.0125
                      }
                    }
                  ]
                  boundingObject USE A2_Transform
                  physics Physics {
                  }
                }
              }
            ]
            name "solid(2)"
            boundingObject USE A1_Transform
            physics Physics {
            }
          }
        }
        DEF L4J1 HingeJoint {
          jointParameters HingeJointParameters {
            position 3.14
            axis 0 0 1
            anchor -0.1 0.15 0
          }
          device [
            RotationalMotor {
              name "Servo41"
            }
          ]
          endPoint Solid {
            translation -0.0998806 0.15 -1.42681e-05
            rotation 0.0005622220463405378 0.7071079756357186 0.707105363222997 3.140466234838101
            children [
              DEF L2MountServoTransform Pose {
                rotation 1 0 0 -1.5708
                children [
                  DEF MountPoint Shape {
                    appearance PBRAppearance {
                      baseColor 0.380392 0.207843 0.513726
                      metalness 0
                    }
                    geometry Cylinder {
                      height 0.06
                      radius 0.01
                    }
                  }
                ]
              }
              DEF A1_Transform Pose {
                translation 0.0315 0 0
                children [
                  DEF A1 Shape {
                    appearance PBRAppearance {
                      baseColor 0.898039 0.647059 0.0392157
                      metalness 0
                    }
                    geometry Box {
                      size 0.063 0.02 0.02
                    }
                  }
                ]
              }
              DEF L4J2 HingeJoint {
                jointParameters HingeJointParameters {
                  axis 0 0 1
                  anchor 0.063 0 0
                }
                device [
                  DEF Servo12 RotationalMotor {
                    name "Servo42"
                  }
                ]
                endPoint Solid {
                  translation 0.06300000000000001 -4.311275944295536e-18 0
                  children [
                    DEF A2_Transform Pose {
                      translation 0.045 0 0
                      children [
                        DEF A2 Shape {
                          appearance PBRAppearance {
                            baseColor 1 0.470588 0
                            metalness 0
                          }
                          geometry Box {
                            size 0.09 0.02 0.02
                          }
                        }
                      ]
                    }
                    DEF L4J3 HingeJoint {
                      jointParameters HingeJointParameters {
                        axis 0 0 1
                        anchor 0.09 0 0
                      }
                      device [
                        DEF Servo13 RotationalMotor {
                          name "Servo43"
                        }
                      ]
                      endPoint Solid {
                        translation 0.09 0 0
                        children [
                          DEF A3_Transform Pose {
                            translation 0.115 0 0
                            children [
                              DEF A3 Shape {
                                appearance PBRAppearance {
                                  baseColor 0.14902 0.635294 0.411765
                                  metalness 0
                                }
                                geometry Box {
                                  size 0.23 0.02 0.02
                                }
                              }
                            ]
                          }
                          Shape {
                            appearance PBRAppearance {
                              baseColor 0.380392 0.207843 0.513726
                              metalness 0
                            }
                            geometry Cylinder {
                              height 0.025
                              radius 0.0125
                            }
                          }
                        ]
                        boundingObject USE A3_Transform
                        physics Physics {
                        }
                      }
                    }
                    Shape {
                      appearance PBRAppearance {
                        baseColor 0.380392 0.207843 0.513726
                        metalness 0
                      }
                      geometry Cylinder {
                        height 0.025
                        radius 0.0125
                      }
                    }
                  ]
                  boundingObject USE A2_Transform
                  physics Physics {
                  }
                }
              }
            ]
            name "solid(1)"
            boundingObject USE A1_Transform
            physics Physics {
            }
          }
        }
        DEF L1J1 HingeJoint {
          jointParameters HingeJointParameters {
            axis 0 0 1
            anchor 0.1 0.15 0
          }
          device [
            RotationalMotor {
              name "Servo11"
            }
          ]
          endPoint Solid {
            translation 0.1 0.15 -1.42681e-05
            rotation 0.9999999999992331 1.2262625356379814e-06 -1.7305524664364949e-07 1.5708000201914338
            children [
              DEF MountServoTransform Pose {
                rotation 1 0 0 -1.5708
                children [
                  DEF MountPoint Shape {
                    appearance PBRAppearance {
                      baseColor 0.380392 0.207843 0.513726
                      metalness 0
                    }
                    geometry Cylinder {
                      height 0.06
                      radius 0.01
                    }
                  }
                ]
              }
              DEF A1_Transform Pose {
                translation 0.0315 0 0
                children [
                  DEF A1 Shape {
                    appearance PBRAppearance {
                      baseColor 0.898039 0.647059 0.0392157
                      metalness 0
                    }
                    geometry Box {
                      size 0.063 0.02 0.02
                    }
                  }
                ]
              }
              DEF L1J2 HingeJoint {
                jointParameters HingeJointParameters {
                  axis 0 0 1
                  anchor 0.063 0 0
                }
                device [
                  DEF Servo12 RotationalMotor {
                    name "Servo12"
                  }
                ]
                endPoint Solid {
                  translation 0.06300000000000001 -4.311275944295536e-18 0
                  children [
                    DEF A2_Transform Pose {
                      translation 0.045 0 0
                      children [
                        DEF A2 Shape {
                          appearance PBRAppearance {
                            baseColor 1 0.470588 0
                            metalness 0
                          }
                          geometry Box {
                            size 0.09 0.02 0.02
                          }
                        }
                      ]
                    }
                    DEF L1J3 HingeJoint {
                      jointParameters HingeJointParameters {
                        axis 0 0 1
                        anchor 0.09 0 0
                      }
                      device [
                        DEF Servo13 RotationalMotor {
                          name "Servo13"
                        }
                      ]
                      endPoint Solid {
                        translation 0.09 0 0
                        children [
                          DEF A3_Transform Pose {
                            translation 0.115 0 0
                            children [
                              DEF A3 Shape {
                                appearance PBRAppearance {
                                  baseColor 0.14902 0.635294 0.411765
                                  metalness 0
                                }
                                geometry Box {
                                  size 0.23 0.02 0.02
                                }
                              }
                            ]
                          }
                          Shape {
                            appearance PBRAppearance {
                              baseColor 0.380392 0.207843 0.513726
                              metalness 0
                            }
                            geometry Cylinder {
                              height 0.025
                              radius 0.0125
                            }
                          }
                        ]
                        boundingObject USE A3_Transform
                        physics Physics {
                        }
                      }
                    }
                    Shape {
                      appearance PBRAppearance {
                        baseColor 0.380392 0.207843 0.513726
                        metalness 0
                      }
                      geometry Cylinder {
                        height 0.025
                        radius 0.0125
                      }
                    }
                  ]
                  boundingObject USE A2_Transform
                  physics Physics {
                  }
                }
              }
            ]
            boundingObject USE A1_Transform
            physics Physics {
            }
          }
        }
      ]
    }
  ]
  name "Hexapod"
  boundingObject USE BaseTransform
  physics Physics {
  }
  controller "<extern>"
}
